<?xml version="1.0"?>
<robot name="imars_lite" xmlns:xacro="http://ros.org/wiki/xacro">

    <!-- Define robot constants -->
    <xacro:property name="base_radius" value="0.175"/>
    <xacro:property name="base_height" value="0.560"/>

    <xacro:property name="camera_xoff" value="${base_radius - 0.05}"/>
    <xacro:property name="camera_yoff" value="0.0"/>
    <xacro:property name="camera_zoff" value="0.05"/>

    <xacro:property name="leg_length" value="0.610"/>
    <xacro:property name="leg_width" value="0.030"/>
    <xacro:property name="leg_height" value="0.090"/>
    <xacro:property name="leg_angle" value="${65*pi/180}"/>

    <xacro:property name="wheel_radius" value="0.050"/>
    <xacro:property name="wheel_width" value="0.037"/>
    <xacro:property name="wheel_ygap" value="0.175"/>
    <xacro:property name="wheel_xoff" value="0.275"/>
    <xacro:property name="wheel_zoff" value="${0.17 - 0.0508 - 0.034}"/>

    <!-- Define inertial property macros -->
    <xacro:macro name="box_inertia" params="m w h d">
        <inertial>
            <origin xyz="0 0 0" rpy="${pi/2} 0 ${pi/2}"/>
            <mass value="${m}"/>
            <inertia ixx="${(m/12) * (h*h + d*d)}" ixy="0.0" ixz="0.0" iyy="${(m/12) * (w*w + d*d)}" iyz="0.0" izz="${(m/12) * (w*w + h*h)}"/>
        </inertial>
    </xacro:macro>

    <xacro:macro name="cylinder_inertia" params="m r h">
        <inertial>
            <origin xyz="0 0 0" rpy="${pi/2} 0 0" />
            <mass value="${m}"/>
            <inertia ixx="${(m/12) * (3*r*r + h*h)}" ixy = "0" ixz = "0" iyy="${(m/12) * (3*r*r + h*h)}" iyz = "0" izz="${(m/2) * (r*r)}"/>
        </inertial>
    </xacro:macro>
    
    <xacro:macro name="sphere_inertia" params="m r">
        <inertial>
            <mass value="${m}"/>
            <inertia ixx="${(2/5) * m * (r*r)}" ixy="0.0" ixz="0.0" iyy="${(2/5) * m * (r*r)}" iyz="0.0" izz="${(2/5) * m * (r*r)}"/>
        </inertial>
    </xacro:macro>


    <!-- Robot Footprint -->
    <link name="base_footprint"/>

    <joint name="base_joint" type="fixed">
        <parent link="base_footprint"/>
        <child link="base_link"/>
        <origin xyz="0.0 0.0 ${base_height/2 + wheel_zoff + wheel_radius}" rpy="0 ${-4*pi/180} 0"/>
    </joint>

    <!-- Robot Base -->
    <link name="base_link">
        <visual>
            <geometry>
                <cylinder radius="${base_radius}" length="${base_height}"/>
            </geometry>
            <material name="Cyan">
                <color rgba="1.0 1.0 1.0 1.0"/>
            </material>
        </visual>
        <collision>
            <geometry>
                <cylinder radius="${base_radius}" length="${base_height}"/>
            </geometry>
        </collision>
        <xacro:cylinder_inertia m="5.0" r="${base_radius}" h="${base_height}"/>
    </link>

    <!-- Robot Head -->
    <link name="head_link">
        <visual>
            <geometry>
                <sphere radius="${base_radius}"/>
            </geometry>
            <material name="Orange">
                <color rgba="1.0 1.0 1.0 0.5"/>
            </material>
        </visual>
        <collision>
            <geometry>
                <sphere radius="${base_radius}"/>
            </geometry>
        </collision>
        <xacro:sphere_inertia m="0.05" r="${base_radius}"/>
    </link>

    <joint name="head_joint" type="fixed">
        <parent link="base_link"/>
        <child link="head_link"/>
        <origin xyz="0.0 0.0 ${base_height/2}" rpy="0 0 0"/>
    </joint>

    <!-- Depth Camera Intel RS D455 -->
    <xacro:arg name="use_nominal_extrinsics" default="false"/>
    <xacro:include filename="$(find realsense2_description)/urdf/_d455.urdf.xacro" />

    <link name="depth_camera_intermediate_link"/>

    <joint name="depth_camera_joint" type="fixed">
        <parent link="head_link"/>
        <child link="depth_camera_intermediate_link"/>
        <origin xyz="${camera_xoff} ${camera_yoff} ${camera_zoff}" rpy="0 ${-0*pi/180} 0"/>        
    </joint>

    <xacro:sensor_d455 parent="depth_camera_intermediate_link" use_nominal_extrinsics="$(arg use_nominal_extrinsics)">
        <origin xyz="0 0 0" rpy="0 0 0"/>
    </xacro:sensor_d455>

    <!-- P+F 2d-LiDAR ODM 8000 R2100 -->
    <link name="pf_lidar_link">
        <visual>
            <geometry>
                <box size="0.045 0.174 0.081"/>
            </geometry>
            <material name="Green">
                <color rgba="0.196 0.659 0.322 1.0"/>
            </material>
        </visual>

        <collision>
            <geometry>
                <box size="0.045 0.174 0.081"/>                
            </geometry>
        </collision>
        <xacro:box_inertia m="0.250" w="0.174" h="0.081" d="0.045"/>
    </link>

    <joint name="joint_name" type="fixed">
        <parent link="base_link"/>
        <child link="pf_lidar_link"/>
        <origin xyz="0.15 0.0 ${base_height/2 - 0.33}" rpy="0 0 0"/>
    </joint>


    <!-- Robot Legs -->
    <xacro:macro name="leg" params="prefix y_reflect">
        <link name="${prefix}_leg_link">
            <visual>
                <origin xyz="${-leg_length/2 + 0.06} 0 0" rpy="0 0 0"/>
                <geometry>
                    <box size="${leg_length} ${leg_width} ${leg_height}"/>
                </geometry>
                <material name="Black">
                    <color rgba="0 0 0 1.0"/>
                </material>
            </visual>
            <collision>
                <origin xyz="${-leg_length/2 + 0.065} 0 0" rpy="0 0 0"/>
                <geometry>
                    <box size="${leg_length} ${leg_width} ${leg_height}"/>
                </geometry>
            </collision>
            <xacro:box_inertia m="1.0" w="${leg_width}" h="${leg_height}" d="${leg_length}"/>
        </link>

        <joint name="${prefix}_leg_joint" type="fixed">
            <parent link="base_link"/>
            <child link="${prefix}_leg_link"/>
            <origin xyz="0 ${y_reflect} ${base_height/2 - 0.15}" rpy="0 ${-leg_angle} 0"/>
        </joint>
    </xacro:macro>

    <xacro:leg prefix="left" y_reflect="${(base_radius + leg_width/2)}"/>
    <xacro:leg prefix="right" y_reflect="${-(base_radius + leg_width/2)}"/>

    <!-- Rear Wheels -->
    <xacro:macro name="wheel" params="prefix x_reflect y_reflect">
        <link name="${prefix}_wheel_link">
            <visual>
                <origin xyz="0 0 0" rpy="${pi/2} 0 0"/>
                <geometry>
                    <cylinder radius="${wheel_radius}" length="${wheel_width}"/>
                </geometry>
                <material name="Gray">
                    <color rgba="0.5 0.5 0.5 1.0"/>
                </material>
            </visual>
            <collision>
                <origin xyz="0 0 0" rpy="${pi/2} 0 0"/>
                <geometry>
                    <cylinder radius="${wheel_radius}" length="${wheel_width}"/>
                </geometry>
            </collision>
            <xacro:cylinder_inertia m="0.3" r="${wheel_radius}" h="${wheel_width}"/>
        </link>

        <joint name="${prefix}_wheel_joint" type="continuous">
            <parent link="${prefix}_leg_link"/>
            <child link="${prefix}_wheel_link"/>
            <origin xyz="${x_reflect} ${y_reflect} 0" rpy="0 ${leg_angle} 0"/>
            <axis xyz="0 1 0"/>
        </joint>
    </xacro:macro>

    <xacro:wheel prefix="left" x_reflect="${-leg_length + 0.065}" y_reflect="0.0"/>
    <xacro:wheel prefix="right" x_reflect="${-leg_length + 0.065}" y_reflect="0.0"/>
    
    <!-- Front Wheel -->
    <link name="front_wheel_fork_link">
        <visual>
            <geometry>
                <box size="0.05 0.08 0.12"/>
            </geometry>
            <material name="Alu">
                <color rgba="0.516 0.527 0.535 1.0"/>
            </material>
        </visual>
        <collision>
            <geometry>
                <box size="0.05 0.08 0.12"/>
            </geometry>
        </collision>
        <xacro:box_inertia m="0.5" w="0.08" h="0.12" d="0.05"/>
    </link>

    <joint name="front_wheel_fork_joint" type="continuous">
        <parent link="base_link"/>
        <child link="front_wheel_fork_link"/>
        <origin xyz="0.120 0.0 ${-(base_height/2 + 0.06)}" rpy="0 0 0"/>
        <axis xyz="0 0 1"/>
    </joint>

    <link name="front_wheel_link">
        <visual>
            <origin xyz="0 0 0" rpy="${pi/2} 0 0"/>
            <geometry>
                <cylinder radius="${wheel_radius}" length="${wheel_width}"/>
            </geometry>
            <material name="Gray">
                <color rgba="0.5 0.5 0.5 1.0"/>
            </material>
        </visual>
        <collision>
            <origin xyz="0 0 0" rpy="${pi/2} 0 0"/>
            <geometry>
                <cylinder radius="${wheel_radius}" length="${wheel_width}"/>
            </geometry>
        </collision>
        <xacro:cylinder_inertia m="0.3" r="${wheel_radius}" h="${wheel_width}"/>
    </link>

    <joint name="front_wheel_joint" type="continuous">
        <parent link="front_wheel_fork_link"/>
        <child link="front_wheel_link"/>
        <origin xyz="0.0 0.0 ${-(0.12/2-0.008)}" rpy="0 0 0"/>
        <axis xyz="0 1 0"/>
    </joint>

</robot>